Workbook

Sheet PROV. JAWA BARAT
A1: DAFTAR CALON PENERIMA BANTUAN TAHUN 2026
A2: DIREKTORAT JENDERAL PERUMAHAN PERDESAAN
A3: TAHAP IV
A5: NO | B5: KODE DESA/KEL. | C5: NAMA | D5: L/P | E5: NO KTP | F5: NO KK | G5: ALAMAT | H5: DESA/ KELURAHAN | I5: KECAMATAN | J5: KABUPATEN/ KOTA | K5: PROVINSI | L5: DELINEASI | M5: PENGUSUL | N5: STATUS | O5: KETERANGAN | P5: PENGELOMPOKAN DESIL
A6: 1 | B6: 3204162001 | C6: DADANG | D6: L | E6: 3204162202740001 | F6: 3204160304058599 | G6: KP PARAKAN BOLANG RT 003 RW 011 | H6: ARJASARI | I6: ARJASARI | J6: KAB. BANDUNG | K6: JAWA BARAT | L6: PERDESAAN | M6: CUCUN AHMAD SYAMSURIJAL | N6: Belum Pernah menerima bantuan BSPS,FLPP dan BP2BT | O6: Backlog 2 desil 2 | P6: Backlog 2 Desil 1-5 | Q6: 1 | R6: =SUM(Q6:Q19) -> 14
A7: 2 | B7: 3204162001 | C7: ALIT | D7: L | E7: 3204162904740002 | F7: 3204160404053881 | G7: KP CIWARU RT 002 RW 003 | H7: ARJASARI | I7: ARJASARI | J7: KAB. BANDUNG | K7: JAWA BARAT | L7: PERDESAAN | M7: CUCUN AHMAD SYAMSURIJAL | N7: Belum Pernah menerima bantuan BSPS,FLPP dan BP2BT | O7: Backlog 2 desil 3 | P7: Backlog 2 Desil 1-5 | Q7: 1
A8: 3 | B8: 3204162001 | C8: APONG | D8: P | E8: 3204164511450003 | F8: 3204162703080001 | G8: KP MUARA RT 003 RW 015 | H8: ARJASARI | I8: ARJASARI | J8: KAB. BANDUNG | K8: JAWA BARAT | L8: PERDESAAN | M8: CUCUN AHMAD SYAMSURIJAL | N8: Belum Pernah menerima bantuan BSPS,FLPP dan BP2BT | O8: Tidak masuk backlog perumahan desil 1 | P8: Tidak masuk backlog perumahan | Q8: 1
A9: 4 | B9: 3204162001 | C9: TATANG SONDA | D9: L | E9: 3204161202650001 | F9: 3204160304059956 | G9: KP HAUR JAJAR RT 001 RW 002 | H9: ARJASARI | I9: ARJASARI | J9: KAB. BANDUNG | K9: JAWA BARAT | L9: PERDESAAN | M9: CUCUN AHMAD SYAMSURIJAL | N9: Belum Pernah menerima bantuan BSPS,FLPP dan BP2BT | O9: Tidak masuk backlog perumahan desil 1 | P9: Tidak masuk backlog perumahan | Q9: 1
A10: 5 | B10: 3204162001 | C10: NINA KARLINA | D10: P | E10: 3204164509940001 | F10: 3204163009140004 | G10: KP ARJASARI RT 006 RW 005 | H10: ARJASARI | I10: ARJASARI | J10: KAB. BANDUNG | K10: JAWA BARAT | L10: PERDESAAN | M10: CUCUN AHMAD SYAMSURIJAL | N10: Belum Pernah menerima bantuan BSPS,FLPP dan BP2BT | O10: Backlog 2 desil 3 | P10: Backlog 2 Desil 1-5 | Q10: 1
A11: 6 | B11: 3204162001 | C11: IWAN SETIAWAN | D11: L | E11: 3204161106840006 | F11: 3204160910130003 | G11: KP PARAKAN BOLANG RT 004RW 001 | H11: ARJASARI | I11: ARJASARI | J11: KAB. BANDUNG | K11: JAWA BARAT | L11: PERDESAAN | M11: CUCUN AHMAD SYAMSURIJAL | N11: Belum Pernah menerima bantuan BSPS,FLPP dan BP2BT | O11: Backlog 2 desil 1 | P11: Backlog 2 Desil 1-5 | Q11: 1
A12: 7 | B12: 3204162001 | C12: AGUS SUKRIMAN | D12: L | E12: 3204160902760002 | F12: 3204162605150004 | G12: KP ARJASARI RT 002RW 007 | H12: ARJASARI | I12: ARJASARI | J12: KAB. BANDUNG | K12: JAWA BARAT | L12: PERDESAAN | M12: CUCUN AHMAD SYAMSURIJAL | N12: Belum Pernah menerima bantuan BSPS,FLPP dan BP2BT | O12: Backlog 2 desil 3 | P12: Backlog 2 Desil 1-5 | Q12: 1
A13: 8 | B13: 3204162001 | C13: USUP | D13: L | E13: 3204160206510001 | F13: 3204160606130016 | G13: KP.ARJASARI RT 3 RW 8 | H13: ARJASARI | I13: ARJASARI | J13: KAB. BANDUNG | K13: JAWA BARAT | L13: PERDESAAN | M13: CUCUN AHMAD SYAMSURIJAL | N13: Belum Pernah menerima bantuan BSPS,FLPP dan BP2BT | O13: Backlog 2 desil 6 | P13: Backlog 2 Desil 6-10 | Q13: 1
A14: 9 | B14: 3204162001 | C14: NANDANG TARYANA | D14: L | E14: 3204160409880002 | F14: 3204163105130044 | G14: KP ARJASARI RT 2 RW 5 | H14: ARJASARI | I14: ARJASARI | J14: KAB. BANDUNG | K14: JAWA BARAT | L14: PERDESAAN | M14: CUCUN AHMAD SYAMSURIJAL | N14: Belum Pernah menerima bantuan BSPS,FLPP dan BP2BT | O14: Backlog 2 desil 1 | P14: Backlog 2 Desil 1-5 | Q14: 1
A15: 10 | B15: 3204162001 | C15: AJANG NANA MULYANA | D15: L | E15: 3204161212780001 | F15: 3204161912170004 | G15: KP.CIBINGBIN RT 1 RW 4 | H15: ARJASARI | I15: ARJASARI | J15: KAB. BANDUNG | K15: JAWA BARAT | L15: PERDESAAN | M15: CUCUN AHMAD SYAMSURIJAL | N15: Belum Pernah menerima bantuan BSPS,FLPP dan BP2BT | O15: Backlog 2 desil 2 | P15: Backlog 2 Desil 1-5 | Q15: 1
A16: 11 | B16: 3204162001 | C16: ANAN | D16: L | E16: 3204160107680163 | F16: 3204160304058577 | G16: KP SUKAMAJU RT 2 RW 11 | H16: ARJASARI | I16: ARJASARI | J16: KAB. BANDUNG | K16: JAWA BARAT | L16: PERDESAAN | M16: CUCUN AHMAD SYAMSURIJAL | N16: Belum Pernah menerima bantuan BSPS,FLPP dan BP2BT | O16: Tidak masuk backlog perumahan desil 1 | P16: Tidak masuk backlog perumahan | Q16: 1
A17: 12 | B17: 3204162001 | C17: EPON | D17: P | E17: 3204165011400005 | F17: 3204160304180007 | G17: KP.CIBINTINU RT 3 RW 16 | H17: ARJASARI | I17: ARJASARI | J17: KAB. BANDUNG | K17: JAWA BARAT | L17: PERDESAAN | M17: CUCUN AHMAD SYAMSURIJAL | N17: Belum Pernah menerima bantuan BSPS,FLPP dan BP2BT | O17: Backlog 2 desil 3 | P17: Backlog 2 Desil 1-5 | Q17: 1
A18: 13 | B18: 3204162001 | C18: ATING | D18: L | E18: 3204161106540002 | F18: 3204163105130130 | G18: KP CIBINGBIN RT 2 RW 4 | H18: ARJASARI | I18: ARJASARI | J18: KAB. BANDUNG | K18: JAWA BARAT | L18: PERDESAAN | M18: CUCUN AHMAD SYAMSURIJAL | N18: Belum Pernah menerima bantuan BSPS,FLPP dan BP2BT | O18: Backlog 2 desil 3 | P18: Backlog 2 Desil 1-5 | Q18: 1
A19: 14 | B19: 3204162001 | C19: ADANG | D19: L | E19: 3204161507740001 | F19: 3204160606130042 | G19: KP.PARAKAN BOLANG RT 3 RW 11 | H19: ARJASARI | I19: ARJASARI | J19: KAB. BANDUNG | K19: JAWA BARAT | L19: PERDESAAN | M19: CUCUN AHMAD SYAMSURIJAL | N19: Belum Pernah menerima bantuan BSPS,FLPP dan BP2BT | O19: Backlog 2 desil 3 | P19: Backlog 2 Desil 1-5 | Q19: 1
A20: 15 | B20: 3204162010 | C20: DESI RAHMAWATI | D20: P | E20: 3204165512960007 | F20: 3204160509170005 | G20: KP CIKIARA RT 003 RW 009 | H20: RANCAKOLE | I20: ARJASARI | J20: KAB. BANDUNG | K20: JAWA BARAT | L20: PERDESAAN | M20: CUCUN AHMAD SYAMSURIJAL | N20: Belum Pernah menerima bantuan BSPS,FLPP dan BP2BT | O20: Backlog 1 desil 3 | P20: Backlog 1 Desil 1-5 | Q20: 1 | R20: =SUM(Q20:Q32) -> 13
A21: 16 | B21: 3204162010 | C21: YADI | D21: L | E21: 3204160806860002 | F21: 3204161810060011 | G21: KP PASIRBATU RT 001 RW 008 | H21: RANCAKOLE | I21: ARJASARI | J21: KAB. BANDUNG | K21: JAWA BARAT | L21: PERDESAAN | M21: CUCUN AHMAD SYAMSURIJAL | N21: Belum Pernah menerima bantuan BSPS,FLPP dan BP2BT | O21: Backlog 2 desil 4 | P21: Backlog 2 Desil 1-5 | Q21: 1
A22: 17 | B22: 3204162010 | C22: ODIH | D22: L | E22: 3204160707640004 | F22: 3204162901130058 | G22: KP PASIRLETIK RT 002 RW 016 | H22: RANCAKOLE | I22: ARJASARI | J22: KAB. BANDUNG | K22: JAWA BARAT | L22: PERDESAAN | M22: CUCUN AHMAD SYAMSURIJAL | N22: Belum Pernah menerima bantuan BSPS,FLPP dan BP2BT | O22: Tidak masuk backlog perumahan desil 2 | P22: Tidak masuk backlog perumahan | Q22: 1
A23: 18 | B23: 3204162010 | C23: WAHYA | D23: L | E23: 3204160101740005 | F23: 3204160404055446 | G23: KP PASIRSEREH RT 001 RW 012 | H23: RANCAKOLE | I23: ARJASARI | J23: KAB. BANDUNG | K23: JAWA BARAT | L23: PERDESAAN | M23: CUCUN AHMAD SYAMSURIJAL | N23: Belum Pernah menerima bantuan BSPS,FLPP dan BP2BT | O23: Backlog 2 desil 1 | P23: Backlog 2 Desil 1-5 | Q23: 1
A24: 19 | B24: 3204162010 | C24: DELA | D24: P | E24: 3204165810830007 | F24: 3204160807080163 | G24: KP POJOK RT 003 RW 010 | H24: RANCAKOLE | I24: ARJASARI | J24: KAB. BANDUNG | K24: JAWA BARAT | L24: PERDESAAN | M24: CUCUN AHMAD SYAMSURIJAL | N24: Belum Pernah menerima bantuan BSPS,FLPP dan BP2BT | O24: Backlog 2 desil 1 | P24: Backlog 2 Desil 1-5 | Q24: 1
A25: 20 | B25: 3204162010 | C25: DEDE NY | D25: P | E25: 3204165103780004 | F25: 3204160404055385 | G25: KP CIDODOL RT 002 RW 011 | H25: RANCAKOLE | I25: ARJASARI | J25: KAB. BANDUNG | K25: JAWA BARAT | L25: PERDESAAN | M25: CUCUN AHMAD SYAMSURIJAL | N25: Belum Pernah menerima bantuan BSPS,FLPP dan BP2BT | O25: Tidak masuk backlog perumahan desil 5 | P25: Tidak masuk backlog perumahan | Q25: 1
A26: 21 | B26: 3204162010 | C26: DERI SULAEMAN | D26: L | E26: 3204161105920002 | F26: 3204162110130016 | G26: KP CIDODOL RT 001 RW 011 | H26: RANCAKOLE | I26: ARJASARI | J26: KAB. BANDUNG | K26: JAWA BARAT | L26: PERDESAAN | M26: CUCUN AHMAD SYAMSURIJAL | N26: Belum Pernah menerima bantuan BSPS,FLPP dan BP2BT | O26: Tidak masuk backlog perumahan desil 3 | P26: Tidak masuk backlog perumahan | Q26: 1
A27: 22 | B27: 3204162010 | C27: TARMIDI | D27: L | E27: 3175070903740006 | F27: 3173031603111020 | G27: KP RANCAKOLE RT 001 RW 007 | H27: RANCAKOLE | I27: ARJASARI | J27: KAB. BANDUNG | K27: JAWA BARAT | L27: PERDESAAN | M27: CUCUN AHMAD SYAMSURIJAL | N27: Belum Pernah menerima bantuan BSPS,FLPP dan BP2BT | O27: Backlog 2 desil 4 | P27: Backlog 2 Desil 1-5 | Q27: 1
A28: 23 | B28: 3204162010 | C28: PIPIN SUPRIATNA | D28: L | E28: 3204161404900002 | F28: 3275032604180017 | G28: KP PASIRTENGAH RT 001 RW 007 | H28: RANCAKOLE | I28: ARJASARI | J28: KAB. BANDUNG | K28: JAWA BARAT | L28: PERDESAAN | M28: CUCUN AHMAD SYAMSURIJAL | N28: Belum Pernah menerima bantuan BSPS,FLPP dan BP2BT | O28: Backlog 1 desil 5 | P28: Backlog 1 Desil 1-5 | Q28: 1
A29: 24 | B29: 3204162010 | C29: LALA NURHADI | D29: L | E29: 3204160103660005 | F29: 3204161510120002 | G29: KP BAHUAN RT 002 RW 014 | H29: RANCAKOLE | I29: ARJASARI | J29: KAB. BANDUNG | K29: JAWA BARAT | L29: PERDESAAN | M29: CUCUN AHMAD SYAMSURIJAL | N29: Belum Pernah menerima bantuan BSPS,FLPP dan BP2BT | O29: Backlog 2 desil 3 | P29: Backlog 2 Desil 1-5 | Q29: 1
A30: 25 | B30: 3204162010 | C30: NONENG MULYANI | D30: P | E30: 3204164107830186 | F30: 3204160705120004 | G30: KP RANCASELANG RT 001 RW 013 | H30: RANCAKOLE | I30: ARJASARI | J30: KAB. BANDUNG | K30: JAWA BARAT | L30: PERDESAAN | M30: CUCUN AHMAD SYAMSURIJAL | N30: Belum Pernah menerima bantuan BSPS,FLPP dan BP2BT | O30: Tidak masuk backlog perumahan desil 1 | P30: Tidak masuk backlog perumahan | Q30: 1
A31: 26 | B31: 3204162010 | C31: AKRI | D31: L | E31: 3204160606650003 | F31: 3204160404056505 | G31: KP RANCASELANG RT 003 RW 013 | H31: RANCAKOLE | I31: ARJASARI | J31: KAB. BANDUNG | K31: JAWA BARAT | L31: PERDESAAN | M31: CUCUN AHMAD SYAMSURIJAL | N31: Belum Pernah menerima bantuan BSPS,FLPP dan BP2BT | O31: Backlog 2 desil 1 | P31: Backlog 2 Desil 1-5 | Q31: 1
A32: 27 | B32: 3204162010 | C32: MUHAMAD ADZCA FIRMANSYAH | D32: L | E32: 3204161712040004 | F32: 3204162811250007 | G32: KP PASIRSEREH RT 003 RW 012 | H32: RANCAKOLE | I32: ARJASARI | J32: KAB. BANDUNG | K32: JAWA BARAT | L32: PERDESAAN | M32: CUCUN AHMAD SYAMSURIJAL | N32: Belum Pernah menerima bantuan BSPS,FLPP dan BP2BT | P32: - | Q32: 1
A33: 28 | B33: 3204321004 | C33: TATANG WAHYUDI | D33: L | E33: 3204322710820001 | F33: 3204320304200002 | G33: KP CIKADU RT 07 RW 02 | H33: JELEKONG | I33: BALEENDAH | J33: KAB. BANDUNG | K33: JAWA BARAT | L33: PERDESAAN | M33: CUCUN AHMAD SYAMSURIJAL | N33: Belum Pernah menerima bantuan BSPS,FLPP dan BP2BT | O33: Backlog 2 desil 4 | P33: Backlog 2 Desil 1-5 | Q33: 1 | R33: =SUM(Q33:Q46) -> 14
A34: 29 | B34: 3204321004 | C34: AGUS SOLIHIN | D34: L | E34: 3204321612800002 | F34: 3204320806120005 | G34: KP CIKADU RT 07 RW 02 | H34: JELEKONG | I34: BALEENDAH | J34: KAB. BANDUNG | K34: JAWA BARAT | L34: PERDESAAN | M34: CUCUN AHMAD SYAMSURIJAL | N34: Belum Pernah menerima bantuan BSPS,FLPP dan BP2BT | O34: Backlog 2 desil 4 | P34: Backlog 2 Desil 1-5 | Q34: 1
A35: 30 | B35: 3204321004 | C35: MAMAN SUHERMAN | D35: L | E35: 3204321008660010 | F35: 3204321611050133 | G35: KP GUGUNUNGAN RT 06 RW 05 | H35: JELEKONG | I35: BALEENDAH | J35: KAB. BANDUNG | K35: JAWA BARAT | L35: PERDESAAN | M35: CUCUN AHMAD SYAMSURIJAL | N35: Belum Pernah menerima bantuan BSPS,FLPP dan BP2BT | O35: Backlog 2 desil 4 | P35: Backlog 2 Desil 1-5 | Q35: 1
A36: 31 | B36: 3204321004 | C36: SUMIATI | D36: P | E36: 3204324507690015 | F36: 3204322511050036 | G36: KP GUGUNUNGAN RT 01 RW 05 | H36: JELEKONG | I36: BALEENDAH | J36: KAB. BANDUNG | K36: JAWA BARAT | L36: PERDESAAN | M36: CUCUN AHMAD SYAMSURIJAL | N36: Belum Pernah menerima bantuan BSPS,FLPP dan BP2BT | O36: Backlog 2 desil 4 | P36: Backlog 2 Desil 1-5 | Q36: 1
A37: 32 | B37: 3204321004 | C37: ERWIN ERIANSYAH | D37: L | E37: 3205150504990002 | F37: 3206153001190002 | G37: KP GUGUNUNGAN RT 04 RW 05 | H37: JELEKONG | I37: BALEENDAH | J37: KAB. BANDUNG | K37: JAWA BARAT | L37: PERDESAAN | M37: CUCUN AHMAD SYAMSURIJAL | N37: Belum Pernah menerima bantuan BSPS,FLPP dan BP2BT | O37: Backlog 2 desil 1 | P37: Backlog 2 Desil 1-5 | Q37: 1
A38: 33 | B38: 3204321004 | C38: ENAN SUGANDI | D38: L | E38: 3204322009740012 | F38: 3204321202140014 | G38: KP GUGUNUNGAN RT 02 RW 05 | H38: JELEKONG | I38: BALEENDAH | J38: KAB. BANDUNG | K38: JAWA BARAT | L38: PERDESAAN | M38: CUCUN AHMAD SYAMSURIJAL | N38: Belum Pernah menerima bantuan BSPS,FLPP dan BP2BT | O38: Backlog 2 desil 2 | P38: Backlog 2 Desil 1-5 | Q38: 1
A39: 34 | B39: 3204321004 | C39: IYAN | D39: L | E39: 3204322909690002 | F39: 3204323003054062 | G39: KP GUGUNUNGAN RT 03 RW 05 | H39: JELEKONG | I39: BALEENDAH | J39: KAB. BANDUNG | K39: JAWA BARAT | L39: PERDESAAN | M39: CUCUN AHMAD SYAMSURIJAL | N39: Belum Pernah menerima bantuan BSPS,FLPP dan BP2BT | O39: Backlog 2 desil 1 | P39: Backlog 2 Desil 1-5 | Q39: 1
A40: 35 | B40: 3204321004 | C40: ODANG SUTISNA | D40: L | E40: 3204320907750006 | F40: 3204320112120167 | G40: KP JELEKONG RT 03 RW 02 | H40: JELEKONG | I40: BALEENDAH | J40: KAB. BANDUNG | K40: JAWA BARAT | L40: PERDESAAN | M40: CUCUN AHMAD SYAMSURIJAL | N40: Belum Pernah menerima bantuan BSPS,FLPP dan BP2BT | O40: Backlog 2 desil 4 | P40: Backlog 2 Desil 1-5 | Q40: 1
A41: 36 | B41: 3204321004 | C41: ASEP SURYANA | D41: L | E41: 3204320502920017 | F41: 3204320211220008 | G41: KP SUKAJADI RT 02 RW 12 | H41: JELEKONG | I41: BALEENDAH | J41: KAB. BANDUNG | K41: JAWA BARAT | L41: PERDESAAN | M41: CUCUN AHMAD SYAMSURIJAL | N41: Belum Pernah menerima bantuan BSPS,FLPP dan BP2BT | O41: Backlog 2 desil 3 | P41: Backlog 2 Desil 1-5 | Q41: 1
...

Sheet DATA PERDESA
A1: No | B1: Nama Desa | C1: Nama Kecamatan | D1: Jumlah Alokasi | E1: TOTAL ALOKASI | F1: TFL Teknik | G1: TFL Pemberdayaan | H1: Kontak PIC Lapangan | I1: Nama PIC Lapangan
A2: 1 | B2: ='PROV. JAWA BARAT'!H6 -> ARJASARI | C2: ='PROV. JAWA BARAT'!I6 -> ARJASARI | D2: ='PROV. JAWA BARAT'!R6 -> 14 | E2: =SUM(D2:D5) -> 55 | F2: Restha Rizky Fazriani | G2: Rizky Diyah Purwanti
A3: 2 | B3: ='PROV. JAWA BARAT'!H20 -> RANCAKOLE | C3: ='PROV. JAWA BARAT'!I20 -> ARJASARI | D3: ='PROV. JAWA BARAT'!R20 -> 13
A4: 5 | B4: ='PROV. JAWA BARAT'!H62 -> PASIRMULYA | C4: ='PROV. JAWA BARAT'!I62 -> BANJARAN | D4: ='PROV. JAWA BARAT'!R62 -> 15
A5: 6 | B5: ='PROV. JAWA BARAT'!H77 -> SINDANGPANON | C5: ='PROV. JAWA BARAT'!I77 -> BANJARAN | D5: ='PROV. JAWA BARAT'!R77 -> 13
A6: 3 | B6: ='PROV. JAWA BARAT'!H33 -> JELEKONG | C6: ='PROV. JAWA BARAT'!I33 -> BALEENDAH | D6: ='PROV. JAWA BARAT'!R33 -> 14 | E6: =SUM(D6:D9) -> 52 | F6: Karina Salsabila | G6: Asri Indah Lestari Nuraeni
A7: 4 | B7: ='PROV. JAWA BARAT'!H47 -> WARGAMEKAR | C7: ='PROV. JAWA BARAT'!I47 -> BALEENDAH | D7: ='PROV. JAWA BARAT'!R47 -> 15
A8: 22 | B8: ='PROV. JAWA BARAT'!H301 -> SUKAPURA | C8: ='PROV. JAWA BARAT'!I301 -> DAYEUHKOLOT | D8: ='PROV. JAWA BARAT'!R301 -> 11
A9: 7 | B9: ='PROV. JAWA BARAT'!H90 -> BOJONGSOANG | C9: ='PROV. JAWA BARAT'!I90 -> BOJONGSOANG | D9: ='PROV. JAWA BARAT'!R90 -> 12
A10: 12 | B10: ='PROV. JAWA BARAT'!H165 -> CILENGKRANG | C10: ='PROV. JAWA BARAT'!I165 -> CILENGKRANG | D10: ='PROV. JAWA BARAT'!R165 -> 13 | E10: =SUM(D10:D13) -> 52 | F10: Aris Soleh Solihin | G10: Maryana Saumi Ulfah
A11: 13 | B11: ='PROV. JAWA BARAT'!H178 -> GIRIMEKAR | C11: ='PROV. JAWA BARAT'!I178 -> CILENGKRANG | D11: ='PROV. JAWA BARAT'!R178 -> 15
A12: 16 | B12: ='PROV. JAWA BARAT'!H224 -> CIBEUNYING | C12: ='PROV. JAWA BARAT'!I224 -> CIMENYAN | D12: ='PROV. JAWA BARAT'!R224 -> 14
A13: 17 | B13: ='PROV. JAWA BARAT'!H238 -> MEKARSALUYU | C13: ='PROV. JAWA BARAT'!I238 -> CIMENYAN | D13: ='PROV. JAWA BARAT'!R238 -> 10
A14: 27 | B14: ='PROV. JAWA BARAT'!H367 -> GAJAH MEKAR | C14: ='PROV. JAWA BARAT'!I367 -> KUTAWARINGIN | D14: ='PROV. JAWA BARAT'!R367 -> 19 | E14: =SUM(D14:D16) -> 51 | F14: Rike Rindiany | G14: Maulana Hasan
A15: 28 | B15: ='PROV. JAWA BARAT'!H386 -> JATISARI | C15: ='PROV. JAWA BARAT'!I386 -> KUTAWARINGIN | D15: ='PROV. JAWA BARAT'!R386 -> 16
A16: 32 | B16: ='PROV. JAWA BARAT'!H447 -> CIGONDEWAH HILIR | C16: ='PROV. JAWA BARAT'!I447 -> MARGAASIH | D16: ='PROV. JAWA BARAT'!R447 -> 16
A17: 41 | B17: ='PROV. JAWA BARAT'!H584 -> ALAMENDAH | C17: ='PROV. JAWA BARAT'!I584 -> RANCABALI | D17: ='PROV. JAWA BARAT'!R584 -> 13 | E17: =SUM(D17:D21) -> 59 | F17: Muh Ridwan Adipratama
A18: 42 | B18: ='PROV. JAWA BARAT'!H597 -> CIPELAH | C18: ='PROV. JAWA BARAT'!I597 -> RANCABALI | D18: ='PROV. JAWA BARAT'!R597 -> 13
A19: 20 | B19: ='PROV. JAWA BARAT'!H278 -> CIWIDEY | C19: ='PROV. JAWA BARAT'!I278 -> CIWIDEY | D19: ='PROV. JAWA BARAT'!R278 -> 8
A20: 21 | B20: ='PROV. JAWA BARAT'!H286 -> RAWABOGO | C20: ='PROV. JAWA BARAT'!I286 -> CIWIDEY | D20: ='PROV. JAWA BARAT'!R286 -> 15
A21: 39 | B21: ='PROV. JAWA BARAT'!H562 -> CIBODAS | C21: ='PROV. JAWA BARAT'!I562 -> PASIRJAMBU | D21: ='PROV. JAWA BARAT'!R569 -> 10
A22: 8 | B22: ='PROV. JAWA BARAT'!H102 -> BABAKAN PEUTEUY | C22: ='PROV. JAWA BARAT'!I102 -> CICALENGKA | D22: ='PROV. JAWA BARAT'!R102 -> 10 | E22: =SUM(D22:D24) -> 49 | G22: Leila Nursaileha
A23: 9 | B23: ='PROV. JAWA BARAT'!H112 -> TANJUNGWANGI | C23: ='PROV. JAWA BARAT'!I112 -> CICALENGKA | D23: ='PROV. JAWA BARAT'!R112 -> 19
A24: 10 | B24: ='PROV. JAWA BARAT'!H131 -> CIHANYIR | C24: ='PROV. JAWA BARAT'!I131 -> CIKANCUNG | D24: ='PROV. JAWA BARAT'!R131 -> 20
A25: 18 | B25: ='PROV. JAWA BARAT'!H248 -> SARIMAHI | C25: ='PROV. JAWA BARAT'!I248 -> CIPARAY | D25: ='PROV. JAWA BARAT'!R248 -> 15 | E25: =SUM(D25:D27) -> 49 | F25: Casare Adi Nugraha | G25: Septian Kurnia Sandi
A26: 19 | B26: ='PROV. JAWA BARAT'!H263 -> SUMBERSARI | C26: ='PROV. JAWA BARAT'!I263 -> CIPARAY | D26: ='PROV. JAWA BARAT'!R263 -> 15
A27: 30 | B27: ='PROV. JAWA BARAT'!H415 -> MAJASETRA | C27: ='PROV. JAWA BARAT'!I415 -> MAJALAYA | D27: ='PROV. JAWA BARAT'!R415 -> 19
A28: 14 | B28: ='PROV. JAWA BARAT'!H193 -> CILEUNYI KULON | C28: ='PROV. JAWA BARAT'!I193 -> CILEUNYI | D28: ='PROV. JAWA BARAT'!R193 -> 15 | E28: =SUM(D28:D30) -> 49 | G28: Mohamad Sandy Suhendar
A29: 11 | B29: ='PROV. JAWA BARAT'!H151 -> CILULUK | C29: ='PROV. JAWA BARAT'!I151 -> CIKANCUNG | D29: ='PROV. JAWA BARAT'!R151 -> 14
A30: 33 | B30: ='PROV. JAWA BARAT'!H463 -> CIARO | C30: ='PROV. JAWA BARAT'!I463 -> NAGREG | D30: ='PROV. JAWA BARAT'!R463 -> 20
A31: 23 | B31: ='PROV. JAWA BARAT'!H312 -> CIBEET | C31: ='PROV. JAWA BARAT'!I312 -> IBUN | D31: ='PROV. JAWA BARAT'!R312 -> 15 | E31: =SUM(D31:D33) -> 50 | F31: Riska Arie Haryanti | G31: Ujang Supriatna
A32: 24 | B32: ='PROV. JAWA BARAT'!H327 -> LAMPEGAN | C32: ='PROV. JAWA BARAT'!I327 -> IBUN | D32: ='PROV. JAWA BARAT'!R327 -> 15
A33: 38 | B33: ='PROV. JAWA BARAT'!H542 -> LOA | C33: ='PROV. JAWA BARAT'!I542 -> PASEH | D33: ='PROV. JAWA BARAT'!R542 -> 20
A34: 43 | B34: ='PROV. JAWA BARAT'!H610 -> BOJONGEMAS | C34: ='PROV. JAWA BARAT'!I610 -> SOLOKANJERUK | D34: ='PROV. JAWA BARAT'!R610 -> 15 | E34: =SUM(D34:D36) -> 50 | G34: Sri Sayekti
A35: 44 | B35: ='PROV. JAWA BARAT'!H625 -> CIBODAS | C35: ='PROV. JAWA BARAT'!I625 -> SOLOKANJERUK | D35: ='PROV. JAWA BARAT'!R625 -> 15
A36: 45 | B36: ='PROV. JAWA BARAT'!H640 -> PADAMUKTI | C36: ='PROV. JAWA BARAT'!I640 -> SOLOKANJERUK | D36: ='PROV. JAWA BARAT'!R640 -> 20
A37: 46 | B37: ='PROV. JAWA BARAT'!H660 -> PANYADAP | C37: ='PROV. JAWA BARAT'!I660 -> SOLOKANJERUK | D37: ='PROV. JAWA BARAT'!R660 -> 21 | E37: =SUM(D37:D39) -> 54 | F37: Triadi Alamsyah | G37: Lathifah Nasayyidah Sopiah
A38: 29 | B38: ='PROV. JAWA BARAT'!H402 -> MAJAKERTA | C38: ='PROV. JAWA BARAT'!I402 -> MAJALAYA | D38: ='PROV. JAWA BARAT'!R402 -> 14
A39: 35 | B39: ='PROV. JAWA BARAT'!H500 -> PANGAUBAN | C39: ='PROV. JAWA BARAT'!I500 -> PACET | D39: ='PROV. JAWA BARAT'!R500 -> 19
A40: 25 | B40: ='PROV. JAWA BARAT'!H342 -> CIKEMBANG | C40: ='PROV. JAWA BARAT'!I342 -> KERTASARI | D40: ='PROV. JAWA BARAT'!R342 -> 12 | E40: =SUM(D40:D43) -> 54 | F40: Arizal M Saleh | G40: Fikri Muhamad Ikbal
...

Sheet DATA PERKECAMATAN
A1: No | B1: Nama Desa | C1: Nama Kecamatan | D1: Jumlah Alokasi | E1: Alokasi perkecamatan
A2: 1 | B2: ='PROV. JAWA BARAT'!H6 -> ARJASARI | C2: ='PROV. JAWA BARAT'!I6 -> ARJASARI | D2: ='PROV. JAWA BARAT'!R6 -> 14 | E2: =SUM(D2:D3) -> 27
A3: 2 | B3: ='PROV. JAWA BARAT'!H20 -> RANCAKOLE | C3: ='PROV. JAWA BARAT'!I20 -> ARJASARI | D3: ='PROV. JAWA BARAT'!R20 -> 13
A4: 3 | B4: ='PROV. JAWA BARAT'!H33 -> JELEKONG | C4: ='PROV. JAWA BARAT'!I33 -> BALEENDAH | D4: ='PROV. JAWA BARAT'!R33 -> 14 | E4: =SUM(D4:D5) -> 29
A5: 4 | B5: ='PROV. JAWA BARAT'!H47 -> WARGAMEKAR | C5: ='PROV. JAWA BARAT'!I47 -> BALEENDAH | D5: ='PROV. JAWA BARAT'!R47 -> 15
A6: 5 | B6: ='PROV. JAWA BARAT'!H62 -> PASIRMULYA | C6: ='PROV. JAWA BARAT'!I62 -> BANJARAN | D6: ='PROV. JAWA BARAT'!R62 -> 15 | E6: =SUM(D6:D7) -> 28
A7: 6 | B7: ='PROV. JAWA BARAT'!H77 -> SINDANGPANON | C7: ='PROV. JAWA BARAT'!I77 -> BANJARAN | D7: ='PROV. JAWA BARAT'!R77 -> 13
A8: 7 | B8: ='PROV. JAWA BARAT'!H90 -> BOJONGSOANG | C8: ='PROV. JAWA BARAT'!I90 -> BOJONGSOANG | D8: ='PROV. JAWA BARAT'!R90 -> 12 | E8: =D8 -> 12
A9: 8 | B9: ='PROV. JAWA BARAT'!H102 -> BABAKAN PEUTEUY | C9: ='PROV. JAWA BARAT'!I102 -> CICALENGKA | D9: ='PROV. JAWA BARAT'!R102 -> 10 | E9: =SUM(D9:D10) -> 29
A10: 9 | B10: ='PROV. JAWA BARAT'!H112 -> TANJUNGWANGI | C10: ='PROV. JAWA BARAT'!I112 -> CICALENGKA | D10: ='PROV. JAWA BARAT'!R112 -> 19
A11: 10 | B11: ='PROV. JAWA BARAT'!H131 -> CIHANYIR | C11: ='PROV. JAWA BARAT'!I131 -> CIKANCUNG | D11: ='PROV. JAWA BARAT'!R131 -> 20 | E11: =SUM(D11:D12) -> 34
A12: 11 | B12: ='PROV. JAWA BARAT'!H151 -> CILULUK | C12: ='PROV. JAWA BARAT'!I151 -> CIKANCUNG | D12: ='PROV. JAWA BARAT'!R151 -> 14
A13: 12 | B13: ='PROV. JAWA BARAT'!H165 -> CILENGKRANG | C13: ='PROV. JAWA BARAT'!I165 -> CILENGKRANG | D13: ='PROV. JAWA BARAT'!R165 -> 13 | E13: =SUM(D13:D14) -> 28
A14: 13 | B14: ='PROV. JAWA BARAT'!H178 -> GIRIMEKAR | C14: ='PROV. JAWA BARAT'!I178 -> CILENGKRANG | D14: ='PROV. JAWA BARAT'!R178 -> 15
A15: 14 | B15: ='PROV. JAWA BARAT'!H193 -> CILEUNYI KULON | C15: ='PROV. JAWA BARAT'!I193 -> CILEUNYI | D15: ='PROV. JAWA BARAT'!R193 -> 15 | E15: =D15 -> 15
A16: 15 | B16: ='PROV. JAWA BARAT'!H208 -> PASIRHUNI | C16: ='PROV. JAWA BARAT'!I208 -> CIMAUNG | D16: ='PROV. JAWA BARAT'!R208 -> 16 | E16: =D16 -> 16
A17: 16 | B17: ='PROV. JAWA BARAT'!H224 -> CIBEUNYING | C17: ='PROV. JAWA BARAT'!I224 -> CIMENYAN | D17: ='PROV. JAWA BARAT'!R224 -> 14 | E17: =SUM(D17:D18) -> 24
A18: 17 | B18: ='PROV. JAWA BARAT'!H238 -> MEKARSALUYU | C18: ='PROV. JAWA BARAT'!I238 -> CIMENYAN | D18: ='PROV. JAWA BARAT'!R238 -> 10
A19: 18 | B19: ='PROV. JAWA BARAT'!H248 -> SARIMAHI | C19: ='PROV. JAWA BARAT'!I248 -> CIPARAY | D19: ='PROV. JAWA BARAT'!R248 -> 15 | E19: =SUM(D19:D20) -> 30
A20: 19 | B20: ='PROV. JAWA BARAT'!H263 -> SUMBERSARI | C20: ='PROV. JAWA BARAT'!I263 -> CIPARAY | D20: ='PROV. JAWA BARAT'!R263 -> 15
A21: 20 | B21: ='PROV. JAWA BARAT'!H278 -> CIWIDEY | C21: ='PROV. JAWA BARAT'!I278 -> CIWIDEY | D21: ='PROV. JAWA BARAT'!R278 -> 8 | E21: =SUM(D21:D22) -> 23
A22: 21 | B22: ='PROV. JAWA BARAT'!H286 -> RAWABOGO | C22: ='PROV. JAWA BARAT'!I286 -> CIWIDEY | D22: ='PROV. JAWA BARAT'!R286 -> 15
A23: 22 | B23: ='PROV. JAWA BARAT'!H301 -> SUKAPURA | C23: ='PROV. JAWA BARAT'!I301 -> DAYEUHKOLOT | D23: ='PROV. JAWA BARAT'!R301 -> 11 | E23: =D23 -> 11
A24: 23 | B24: ='PROV. JAWA BARAT'!H312 -> CIBEET | C24: ='PROV. JAWA BARAT'!I312 -> IBUN | D24: ='PROV. JAWA BARAT'!R312 -> 15 | E24: =SUM(D24:D25) -> 30
A25: 24 | B25: ='PROV. JAWA BARAT'!H327 -> LAMPEGAN | C25: ='PROV. JAWA BARAT'!I327 -> IBUN | D25: ='PROV. JAWA BARAT'!R327 -> 15
A26: 25 | B26: ='PROV. JAWA BARAT'!H342 -> CIKEMBANG | C26: ='PROV. JAWA BARAT'!I342 -> KERTASARI | D26: ='PROV. JAWA BARAT'!R342 -> 12 | E26: =SUM(D26:D27) -> 25
A27: 26 | B27: ='PROV. JAWA BARAT'!H354 -> TARUMAJAYA | C27: ='PROV. JAWA BARAT'!I354 -> KERTASARI | D27: ='PROV. JAWA BARAT'!R354 -> 13
A28: 27 | B28: ='PROV. JAWA BARAT'!H367 -> GAJAH MEKAR | C28: ='PROV. JAWA BARAT'!I367 -> KUTAWARINGIN | D28: ='PROV. JAWA BARAT'!R367 -> 19 | E28: =SUM(D28:D29) -> 35
A29: 28 | B29: ='PROV. JAWA BARAT'!H386 -> JATISARI | C29: ='PROV. JAWA BARAT'!I386 -> KUTAWARINGIN | D29: ='PROV. JAWA BARAT'!R386 -> 16
A30: 29 | B30: ='PROV. JAWA BARAT'!H402 -> MAJAKERTA | C30: ='PROV. JAWA BARAT'!I402 -> MAJALAYA | D30: ='PROV. JAWA BARAT'!R402 -> 14 | E30: =SUM(D30:D32) -> 45
A31: 30 | B31: ='PROV. JAWA BARAT'!H415 -> MAJASETRA | C31: ='PROV. JAWA BARAT'!I415 -> MAJALAYA | D31: ='PROV. JAWA BARAT'!R415 -> 19
A32: 31 | B32: ='PROV. JAWA BARAT'!H434 -> SUKAMAJU | C32: ='PROV. JAWA BARAT'!I434 -> MAJALAYA | D32: ='PROV. JAWA BARAT'!R434 -> 12
A33: 32 | B33: ='PROV. JAWA BARAT'!H447 -> CIGONDEWAH HILIR | C33: ='PROV. JAWA BARAT'!I447 -> MARGAASIH | D33: ='PROV. JAWA BARAT'!R447 -> 16 | E33: =D33 -> 16
A34: 33 | B34: ='PROV. JAWA BARAT'!H463 -> CIARO | C34: ='PROV. JAWA BARAT'!I463 -> NAGREG | D34: ='PROV. JAWA BARAT'!R463 -> 20 | E34: =D34 -> 20
A35: 34 | B35: ='PROV. JAWA BARAT'!H483 -> CIKAWAO | C35: ='PROV. JAWA BARAT'!I483 -> PACET | D35: ='PROV. JAWA BARAT'!R483 -> 17 | E35: =SUM(D35:D36) -> 36
A36: 35 | B36: ='PROV. JAWA BARAT'!H500 -> PANGAUBAN | C36: ='PROV. JAWA BARAT'!I500 -> PACET | D36: ='PROV. JAWA BARAT'!R500 -> 19
A37: 36 | B37: ='PROV. JAWA BARAT'!H519 -> LAMAJANG | C37: ='PROV. JAWA BARAT'!I519 -> PANGALENGAN | D37: ='PROV. JAWA BARAT'!R519 -> 15 | E37: =SUM(D37:D38) -> 23
A38: 37 | B38: ='PROV. JAWA BARAT'!H534 -> PULOSARI | C38: ='PROV. JAWA BARAT'!I534 -> PANGALENGAN | D38: ='PROV. JAWA BARAT'!R534 -> 8
A39: 38 | B39: ='PROV. JAWA BARAT'!H542 -> LOA | C39: ='PROV. JAWA BARAT'!I542 -> PASEH | D39: ='PROV. JAWA BARAT'!R542 -> 20 | E39: =D39 -> 20
A40: 39 | B40: ='PROV. JAWA BARAT'!H562 -> CIBODAS | C40: ='PROV. JAWA BARAT'!I562 -> PASIRJAMBU | D40: ='PROV. JAWA BARAT'!R569 -> 10 | E40: =SUM(D40:D41) -> 22
...
